<?xml version="1.0" ?>
<robot name="cheetah">
    <link name="torso">
        <contact>
            <lateral_friction value="1"/>
        </contact>

        <inertial>
            <origin rpy="0 0 0" xyz="0 0 0"/>
            <mass value="1.0"/>
            <inertia ixx="0" ixy="0" ixz="0" iyy="0" iyz="0" izz="0"/>
        </inertial>

        <visual>
            <origin rpy="0 0 0" xyz="0 0 0"/>
            <geometry>
                <cylinder length="1.0" radius="0.023" />
            </geometry>
            <material name="yellow">
                <color rgba="0.95 0.75 0.05 1"/>
            </material>
        </visual>

        <collision>
            <origin rpy="0 0 0" xyz="0 0 0"/>
            <geometry>
                <cylinder length="0.5" radius="0.023" />
            </geometry>
        </collision>
    </link>	

    <link name="bthigh">
        <contact>
            <lateral_friction value="1"/>
        </contact>

        <inertial>
            <origin rpy="0 0 0" xyz="0 0 0.073"/>
            <mass value="1.0"/>
            <inertia ixx="0" ixy="0" ixz="0" iyy="0" iyz="0" izz="0"/>
        </inertial>

        <visual>
            <origin rpy="0 0 0" xyz="0 0 0.073"/>
            <geometry>
                <cylinder length="0.146" radius="0.023" />
            </geometry>
            <material name="green"/>
        </visual>

        <collision>
            <origin rpy="0 0 0" xyz="0 0 0.073"/>
            <geometry>
                <cylinder length="0.1" radius="0.023" />
            </geometry>
        </collision>
    </link>	

    <joint name="bthigh_joint" type="continuous">
        <axis xyz="0 1 0"/>
        <parent link="torso"/>
        <child link="bthigh"/>
        <origin rpy="0 -0.5146474 0" xyz="0 0 -0.5"/>
        <!--<limit effort="100" velocity="100" lower="-0.52" upper="1.05"/>-->
        <joint_properties damping=".0" friction=".0"/>
    </joint>

    <link name="bshin">
        <contact>
            <lateral_friction value="1"/>
        </contact>

        <inertial>
            <origin rpy="0 0 0" xyz="0 0 0.075"/>
            <mass value="1.0"/>
            <inertia ixx="0" ixy="0" ixz="0" iyy="0" iyz="0" izz="0"/>
        </inertial>

        <visual>
            <origin rpy="0 0 0" xyz="0 0 0.075"/>
            <geometry>
                <cylinder length="0.15" radius="0.023" />
            </geometry>
            <material name="green"/>
        </visual>

        <collision>
            <origin rpy="0 0 0" xyz="0 0 0.075"/>
            <geometry>
                <cylinder length="0.1" radius="0.023" />
            </geometry>
        </collision>
    </link>	

    <joint name="bsin_joint" type="continuous">
        <axis xyz="0 1 0"/>
        <parent link="bthigh"/>
        <child link="bshin"/>
        <origin rpy="0 0 0" xyz="0 0 0.146"/>
        <!--<limit effort="100" velocity="100" lower="-0.785" upper="0.785"/> -->
        <joint_properties damping=".0" friction=".0"/>
    </joint>

</robot>

